<mujoco model="bolt">
  <body name="robot" pos="0 0 0.8">
    <!-- <freejoint name="root"/> -->
    <geom name="body_visual" type="mesh" contype="0" conaffinity="0" group="1" density="0" rgba="0.8 0.8 0.8 1" mesh="bolt_body"/>
    <geom name="body_collision" type="mesh" rgba="0.8 0.8 0.8 1" mesh="bolt_body"/>
    <body name="FL_SHOULDER" pos="0 0.0636 0">
      <inertial pos="0.0170826 -0.00446892 -0.0109583" quat="0.380445 0.573263 0.68117 0.250275" mass="0.140043" diaginertia="0.000140999 0.000103321 5.85997e-05"/>
      <joint name="FL_HAA" pos="0 0 0" axis="1 0 0" actuatorfrcrange="-1000 1000"/>
      <geom name="FL_SHOULDER_VISUAL" type="mesh" contype="0" conaffinity="0" group="1" density="0" rgba="0.8 0.8 0.8 1" mesh="bolt_hip_fe_left_side"/>
      <!-- Disables shoulder collision as it resulted in clipping with the body and as a result the should couldn't move -->
      <!-- <geom name="FL_SHOULDER_COLLISION" type="mesh" rgba="0.8 0.8 0.8 1" mesh="bolt_hip_fe_left_side"/> -->
      <body name="FL_UPPER_LEG" pos="0 0.0145 -0.0386">
        <inertial pos="1.377e-05 0.0193585 -0.118707" quat="0.705243 -0.0424536 0.0423607 0.706424" mass="0.148538" diaginertia="0.000417563 0.00041107 2.46069e-05"/>
        <joint name="FL_HFE" pos="0 0 0" axis="0 1 0" actuatorfrcrange="-1000 1000"/>
        <geom name="FL_UPPER_LEG_VISUAL" type="mesh" contype="0" conaffinity="0" group="1" density="0" rgba="0.8 0.8 0.8 1" mesh="upper_leg_200mm_left_side"/>
        <geom name="FL_UPPER_LEG_COLLISION" type="mesh" rgba="0.8 0.8 0.8 1" mesh="upper_leg_200mm_left_side"/>
        <body name="FL_LOWER_LEG" pos="0 0.0374 -0.2">
          <inertial pos="0 0.00836601 -0.116186" quat="0.707082 -0.00588079 0.00588079 0.707082" mass="0.0312724" diaginertia="0.00011713 0.000116139 2.69836e-06"/>
          <joint name="FL_KFE" pos="0 0 0" axis="0 1 0" actuatorfrcrange="-1000 1000"/>
          <geom name="FL_LOWER_LEG_VISUAL" type="mesh" contype="0" conaffinity="0" group="1" density="0" rgba="0.8 0.8 0.8 1" mesh="lower_leg_200mm_left_side"/>
          <geom name="FL_LOWER_LEG_COLLISION" type="mesh" rgba="0.8 0.8 0.8 1" mesh="lower_leg_200mm_left_side"/>
          <geom name="FL_FOOT_VISUAL" pos="0 0.008 -0.21" quat="0.385543 0 0.92269 0" type="mesh" contype="0" conaffinity="0" group="1" density="0" rgba="0.8 0.8 0.8 1" mesh="bolt_foot"/>
          <geom name="FL_FOOT_COLLISION" pos="0 0.008 -0.21" quat="0.385543 0 0.92269 0" type="mesh" rgba="0.8 0.8 0.8 1" mesh="bolt_foot"/>
        </body>
      </body>
    </body>
    <body name="FR_SHOULDER" pos="0 -0.0636 0">
      <inertial pos="0.0170823 0.00447099 -0.0109585" quat="0.250376 0.681095 0.573344 0.380393" mass="0.140044" diaginertia="0.000141003 0.000103316 5.8591e-05"/>
      <joint name="FR_HAA" pos="0 0 0" axis="1 0 0" actuatorfrcrange="-1000 1000"/>
      <geom name="FR_SHOULDER_VISUAL" type="mesh" contype="0" conaffinity="0" group="1" density="0" rgba="0.8 0.8 0.8 1" mesh="bolt_hip_fe_right_side"/>
      <!-- Disables shoulder collision as it resulted in clipping with the body and as a result the should couldn't move -->
      <!-- <geom name="FR_SHOULDER_COLLISION" type="mesh" rgba="0.8 0.8 0.8 1" mesh="bolt_hip_fe_right_side"/> -->
      <body name="FR_UPPER_LEG" pos="0 -0.0145 -0.0386">
        <inertial pos="-1.377e-05 -0.0193585 -0.118707" quat="0.705243 0.0424536 -0.0423607 0.706424" mass="0.148538" diaginertia="0.000417563 0.00041107 2.46069e-05"/>
        <joint name="FR_HFE" pos="0 0 0" axis="0 1 0" actuatorfrcrange="-1000 1000"/>
        <geom name="FR_UPPER_LEG_VISUAL" type="mesh" contype="0" conaffinity="0" group="1" density="0" rgba="0.8 0.8 0.8 1" mesh="upper_leg_200mm_right_side"/>
        <geom name="FR_UPPER_LEG_COLLISION" type="mesh" rgba="0.8 0.8 0.8 1" mesh="upper_leg_200mm_right_side"/>
        <body name="FR_LOWER_LEG" pos="0 -0.0374 -0.2">
          <inertial pos="0 -0.00836601 -0.116186" quat="0.707082 0.00588079 -0.00588079 0.707082" mass="0.0312724" diaginertia="0.00011713 0.000116139 2.69836e-06"/>
          <joint name="FR_KFE" pos="0 0 0" axis="0 1 0" actuatorfrcrange="-1000 1000"/>
          <geom name="FR_LOWER_LEG_VISUAL" type="mesh" contype="0" conaffinity="0" group="1" density="0" rgba="0.8 0.8 0.8 1" mesh="lower_leg_200mm_right_side"/>
          <geom name="FR_LOWER_LEG_COLLISION" type="mesh" rgba="0.8 0.8 0.8 1" mesh="lower_leg_200mm_right_side"/>
          <geom name="FR_FOOT_VISUAL" pos="0 -0.008 -0.21" quat="0.385543 0 0.92269 0" type="mesh" contype="0" conaffinity="0" group="1" density="0" rgba="0.8 0.8 0.8 1" mesh="bolt_foot"/>
          <geom name="FR_FOOT_COLLISION" pos="0 -0.008 -0.21" quat="0.385543 0 0.92269 0" type="mesh" rgba="0.8 0.8 0.8 1" mesh="bolt_foot"/>
        </body>
      </body>
    </body>
  </body>
</mujoco>
