<mujoco>
  <include file="shared.xml"></include>
  <worldbody>
    <include file="floorplane.xml"></include>
    <body name="sim_robot" pos="0 0 0">
      <joint name="slide_z" type="slide" axis="0 0 1"/>
      <include file="robot.xml"></include>
    </body>
  </worldbody>
  <include file="actuators.xml"/>
  <keyframe>
    <!-- Joint Order in Mujoco: FL_HAA FL_HFE FL_KFE FR_HAA FR_HFE FR_KFE -->
    <key name="initial_joint_positions" time="0"
      qpos="0.5
      0.0
      0.5
      -1.0
      0.0
      0.5
      -1.0
      " />
  </keyframe>
  <include file="contacts.xml"/>
</mujoco>
